<?xml version="1.0"?>

<robot xmlns:xacro="http://ros.org/wiki/xacro">

  <xacro:include filename="$(find sq2_ccv_description)/urdf/common.xacro"/>

  <property name="battery_box_length" value="0.208"/>
  <property name="battery_box_width" value="0.208"/>
  <property name="battery_box_height" value="0.5535"/>
  <property name="battery_box_mass" value="20.0"/>

  <xacro:macro name="battery_box" params="parent *joint_origin *joint_axis">
    <joint name="battery_box_joint" type="continuous">
      <insert_block name="joint_origin"/>
      <parent link="${parent}"/>
      <insert_block name="joint_axis"/>
      <limit velocity="30" effort="23"/>
	  <child link="battery_box_link"/>
    </joint>

    <link name="battery_box_link">
      <visual>
		<origin xyz="0 0 0.24675" rpy="0 0 0"/>
        <geometry>
    	  <box size="${battery_box_length} ${battery_box_width} ${battery_box_height}"/>
        </geometry>
      </visual>
      <collision>
		<origin xyz="0 0 0.24675" rpy="0 0 0"/>
        <geometry>
    	  <box size="${battery_box_length} ${battery_box_width} ${battery_box_height}"/>
        </geometry>
      </collision>
      <inertial>
	  <origin xyz="0 0 0.25" rpy="0 0 0"/>
		<mass value="${battery_box_mass}"/>
        <inertia ixx="1" ixy="0" ixz="0" iyz="0" iyy="1" izz="1"/>
      </inertial>
    </link>
  </xacro:macro>

  <xacro:macro name="battery_box_gazebo">
    <gazebo reference="battery_box_link">
      <selfCollide>false</selfCollide>
      <mu1 value="0.05"/>
      <mu2 value="0.05"/>
    </gazebo>
  </xacro:macro>

  <xacro:macro name="battery_box_trans">
    <transmission name="battery_box_trans">
      <type>transmission_interface/SimpleTransmission</type>
      <joint name="battery_box_joint">
        <hardwareInterface>hardware_interface/PositionJointInterface</hardwareInterface>
      </joint>
      <actuator name="battery_box_motor">
        <hardwareInterface>hardware_interface/PositionJointInterface</hardwareInterface>
        <mechanicalReduction>30</mechanicalReduction>
      </actuator>
    </transmission>
  </xacro:macro>

</robot>
