<?xml version="1.0"?>

<robot xmlns:xacro="http://ros.org/wiki/xacro">

  <xacro:include filename="$(find sq2_ccv_description)/urdf/common.xacro"/>

  <property name="pitch2shaft_length" value="0.078"/>
  <property name="pitch2shaft_width" value="0.120"/>
  <property name="pitch2shaft_height" value="0.074"/>
  <property name="pitch2shaft_mass" value="1.0"/>

  <xacro:macro name="pitch2shaft" params="prefix parent *joint_origin *joint_axis">
    <joint name="${prefix}_pitch2shaft_joint" type="revolute">
      <insert_block name="joint_origin"/>
      <parent link="${parent}"/>
      <insert_block name="joint_axis"/>
      <limit velocity="6.28" effort="28" lower="-0.5" upper="0.5"/>
	  <child link="${prefix}_pitch2shaft_link"/>
	  <dynamics damping="0.001"/>
    </joint>

    <link name="${prefix}_pitch2shaft_link">
      <visual>
		<origin xyz="0.03095 0 0" rpy="0 0 0"/>
        <geometry>
    	  <box size="${pitch2shaft_length} ${pitch2shaft_width} ${pitch2shaft_height}"/>
        </geometry>
      </visual>
      <collision>
		<origin xyz="0.03095 0 0" rpy="0 0 0"/>
        <geometry>
    	  <box size="${pitch2shaft_length} ${pitch2shaft_width} ${pitch2shaft_height}"/>
        </geometry>
      </collision>
      <inertial>
		<origin xyz="0.03095 0 0" rpy="0 0 0"/>
        <mass value="5"/>
        <inertia ixx="1" ixy="0" ixz="0" iyz="0" iyy="1" izz="1"/>
      </inertial>
    </link>
  </xacro:macro>

  <xacro:macro name="pitch2shaft_gazebo" params="prefix">
    <gazebo reference="${prefix}_pitch2shaft_link">
      <selfCollide>false</selfCollide>
      <mu1 value="0.05"/>
      <mu2 value="0.05"/>
    </gazebo>
  </xacro:macro>

  <xacro:macro name="pitch2shaft_trans" params="prefix">
    <transmission name="${prefix}_pitch2shaft_trans">
      <type>transmission_interface/SimpleTransmission</type>
      <joint name="${prefix}_pitch2shaft_joint">
        <hardwareInterface>hardware_interface/EffortJointInterface</hardwareInterface>
      </joint>
      <actuator name="${prefix}_pitch2shaft_motor">
        <hardwareInterface>hardware_interface/EffortJointInterface</hardwareInterface>
        <mechanicalReduction>30</mechanicalReduction>
      </actuator>
    </transmission>
  </xacro:macro>

</robot>
